Workbook

Sheet Feature_Controls
A1: Features | B1: View | C1: Manage | D1: Control | E1: Process | F1: Limitations | G1: Additional Limitations | H1: Column1
A2: Accounts | B2: Yes | C2: No | D2: No | E2: No | F2: Available in all packages | H2: =COUNTIF(Feature_Controls[[#This Row],[View]:[Process]],"Yes") -> 1
A3: Allocations (New Issues) | B3: No | C3: Yes | D3: No | E3: No | F3: cannot be assigned without orders | H3: =COUNTIF(Feature_Controls[[#This Row],[View]:[Process]],"Yes") -> 1
A4: Bulk Document Upload | B4: Yes | C4: No | D4: No | E4: No | F4: Available in all packages | H4: =COUNTIF(Feature_Controls[[#This Row],[View]:[Process]],"Yes") -> 1
A5: CRMA | B5: Yes | C5: No | D5: No | E5: No | F5: Available in all packages | H5: =COUNTIF(Feature_Controls[[#This Row],[View]:[Process]],"Yes") -> 1
A6: CRS-FATCA | B6: Yes | C6: Yes | D6: No | E6: No | G6: Manage is not possible without View | H6: =COUNTIF(Feature_Controls[[#This Row],[View]:[Process]],"Yes") -> 2
A7: Compass (Legacy) | B7: Yes | C7: No | D7: No | E7: No | F7: Available in all packages | H7: =COUNTIF(Feature_Controls[[#This Row],[View]:[Process]],"Yes") -> 1
A8: Data Export | B8: Yes | C8: No | D8: No | E8: No | F8: Available in all packages | H8: =COUNTIF(Feature_Controls[[#This Row],[View]:[Process]],"Yes") -> 1
A9: FundFacts/FundFacts History | B9: No | C9: Yes | D9: No | E9: No | F9: cannot be assigned without Trade Allocations | H9: =COUNTIF(Feature_Controls[[#This Row],[View]:[Process]],"Yes") -> 1
A10: Manage Equity Orders | B10: No | C10: Yes | D10: No | E10: No | F10: cannot be assigned without orders | H10: =COUNTIF(Feature_Controls[[#This Row],[View]:[Process]],"Yes") -> 1
A11: Manage Mutual Fund Orders | B11: No | C11: Yes | D11: No | E11: No | F11: cannot be assigned without orders | H11: =COUNTIF(Feature_Controls[[#This Row],[View]:[Process]],"Yes") -> 1
A12: Manage Options Orders | B12: No | C12: Yes | D12: No | E12: No | F12: cannot be assigned without orders | H12: =COUNTIF(Feature_Controls[[#This Row],[View]:[Process]],"Yes") -> 1
A13: MaxLite | B13: Yes | C13: No | D13: No | E13: No | F13: cannot be assigned without Trade Allocations | H13: =COUNTIF(Feature_Controls[[#This Row],[View]:[Process]],"Yes") -> 1
A14: MyPortfolio+ IA | B14: Yes | C14: No | D14: No | E14: No | F14: Available in all packages | H14: =COUNTIF(Feature_Controls[[#This Row],[View]:[Process]],"Yes") -> 1
A15: MyPortfolio+ User Admin | B15: No | C15: Yes | D15: No | E15: No | F15: Only available under client user management | H15: =COUNTIF(Feature_Controls[[#This Row],[View]:[Process]],"Yes") -> 1
A16: Onboarding: Approve Option Applications | B16: No | C16: No | D16: Yes | E16: No | F16: cannot be assigned without Paper Upload | H16: =COUNTIF(Feature_Controls[[#This Row],[View]:[Process]],"Yes") -> 1
A17: Onboarding: Form Applications | B17: Yes | C17: No | D17: No | E17: No | H17: =COUNTIF(Feature_Controls[[#This Row],[View]:[Process]],"Yes") -> 1
A18: Onboarding: Paper Upload | B18: Yes | C18: Yes | D18: Yes | E18: Yes | G18: Possible combinations are: View View + Manage View + Control View + Process | H18: =COUNTIF(Feature_Controls[[#This Row],[View]:[Process]],"Yes") -> 4
A19: Orders | B19: Yes | C19: No | D19: No | E19: No | H19: =COUNTIF(Feature_Controls[[#This Row],[View]:[Process]],"Yes") -> 1
A20: Orders: GIC | B20: No | C20: Yes | D20: No | E20: No | F20: cannot be assigned without orders | H20: =COUNTIF(Feature_Controls[[#This Row],[View]:[Process]],"Yes") -> 1
A21: Orders: MF Uploads | B21: No | C21: Yes | D21: No | E21: No | F21: cannot be assigned without orders | H21: =COUNTIF(Feature_Controls[[#This Row],[View]:[Process]],"Yes") -> 1
A22: Servicing | B22: Yes | C22: Yes | D22: No | E22: No | G22: Manage is not possible without View | H22: =COUNTIF(Feature_Controls[[#This Row],[View]:[Process]],"Yes") -> 2
A23: Servicing: Approvals | B23: No | C23: No | D23: Yes | E23: No | H23: =COUNTIF(Feature_Controls[[#This Row],[View]:[Process]],"Yes") -> 1
A24: Statements | B24: Yes | C24: No | D24: No | E24: No | F24: Available in all packages | H24: =COUNTIF(Feature_Controls[[#This Row],[View]:[Process]],"Yes") -> 1
A25: Tax Documents | B25: Yes | C25: No | D25: No | E25: No | F25: Available in all packages | H25: =COUNTIF(Feature_Controls[[#This Row],[View]:[Process]],"Yes") -> 1
A26: Tools | B26: Yes | C26: No | D26: No | E26: No | F26: Available in all packages | H26: =COUNTIF(Feature_Controls[[#This Row],[View]:[Process]],"Yes") -> 1
A27: Trade Allocations | B27: Yes | C27: Yes | D27: No | E27: No | G27: Manage is not possible without View | H27: =COUNTIF(Feature_Controls[[#This Row],[View]:[Process]],"Yes") -> 2
A28: Trade Allocations: Approvals | B28: No | C28: No | D28: Yes | E28: No | F28: cannot be assigned without Trade Allocations | H28: =COUNTIF(Feature_Controls[[#This Row],[View]:[Process]],"Yes") -> 1
A29: Trade Allocations: Processing | B29: No | C29: No | D29: No | E29: Yes | F29: cannot be assigned without Trade Allocations | H29: =COUNTIF(Feature_Controls[[#This Row],[View]:[Process]],"Yes") -> 1
A30: Trade Confirmations | B30: Yes | C30: No | D30: No | E30: No | F30: Available in all packages | H30: =COUNTIF(Feature_Controls[[#This Row],[View]:[Process]],"Yes") -> 1
A31: Unified Access Requests | B31: Yes | C31: Yes | D31: No | E31: Yes | F31: Only available under client user management | G31: Possible combinations are: View View + Manage View + Process | H31: =COUNTIF(Feature_Controls[[#This Row],[View]:[Process]],"Yes") -> 3
A32: View System Health Events | B32: Yes | C32: No | D32: No | E32: No | H32: =COUNTIF(Feature_Controls[[#This Row],[View]:[Process]],"Yes") -> 1
A33: Web Panagon | B33: Yes | C33: No | D33: No | E33: No | F33: Available in all packages | H33: =COUNTIF(Feature_Controls[[#This Row],[View]:[Process]],"Yes") -> 1

Sheet Rules Summary
A1: Rules Used to Generate the 50 Logical Requirements
A3: Purpose
A4: Identify logical capability-control combinations that may require a supporting preconfigured user package. Feature-level mapping will be assessed separately.
A6: Rule | B6: Application
A7: 1. View-only capabilities remain included | B7: The nine capabilities that only offer View remain visible and are fixed at View in each of the 48 standard combinations.
A8: 2. Four capabilities drive the standard combinations | B8: Client Lifecycle Management, Client Servicing, Order Management and Trade Operations are the capabilities whose controls vary.
A9: 3. None is not treated as a selectable control | B9: Each of the four variable capabilities has a selected control in every standard combination.
A10: 4. Client Servicing Process is excluded | B10: Client Servicing uses View, Manage and Control only. Process is not included in any scenario.
A11: 5. Other valid controls are retained | B11: Lifecycle uses View, Manage, Control and Process; Order Management uses View and Manage; Trade Operations uses View and Manage; Control is excluded.
A12: 6. Manage includes View | B12: Manage is recorded once as the selected control. A separate View plus Manage state is not generated.
A13: 7. User Access Management is exclusive | B13: User Access Management cannot coexist with another capability and is represented by two standalone requirements: View and Manage.
A14: 8. Features are outside this list | B14: This list covers capability-control patterns only. Eligible features will be mapped separately.
A17: Count calculation
A18: Standard combinations | B18: 4 × 3 × 2 × 2 = 48
A19: User Access Management standalone | B19: 2
A20: Total | B20: 50
A22: Important interpretation
A23: This list covers cases where all four main capabilities have a selected control. It does not separately list requests where one or more of the four main capabilities are left out. User Access Management is listed separately because it cannot be combined with any other capability.

Sheet 50 Requirements
A1: Requirement ID | B1: Application Links | C1: Application SSO | D1: Client Inquiry & Insights | E1: Client Lifecycle Management | F1: Client Servicing | G1: Data and Reporting | H1: Fee Management | I1: Investor Portal | J1: Managed Portfolios | K1: Order Management | L1: Reference Data | M1: Trade Operations | N1: Trading Tools | O1: User Access Management
A2: REQ-001 | B2: View | C2: View | D2: View | E2: View | F2: View | G2: View | H2: View | I2: View | J2: View | K2: View | L2: View | M2: View | N2: View | O2: Not applicable
A3: REQ-002 | B3: View | C3: View | D3: View | E3: View | F3: View | G3: View | H3: View | I3: View | J3: View | K3: View | L3: View | M3: Manage | N3: View | O3: Not applicable
A4: REQ-003 | B4: View | C4: View | D4: View | E4: View | F4: View | G4: View | H4: View | I4: View | J4: View | K4: Manage | L4: View | M4: View | N4: View | O4: Not applicable
A5: REQ-004 | B5: View | C5: View | D5: View | E5: View | F5: View | G5: View | H5: View | I5: View | J5: View | K5: Manage | L5: View | M5: Manage | N5: View | O5: Not applicable
A6: REQ-005 | B6: View | C6: View | D6: View | E6: View | F6: Manage | G6: View | H6: View | I6: View | J6: View | K6: View | L6: View | M6: View | N6: View | O6: Not applicable
A7: REQ-006 | B7: View | C7: View | D7: View | E7: View | F7: Manage | G7: View | H7: View | I7: View | J7: View | K7: View | L7: View | M7: Manage | N7: View | O7: Not applicable
A8: REQ-007 | B8: View | C8: View | D8: View | E8: View | F8: Manage | G8: View | H8: View | I8: View | J8: View | K8: Manage | L8: View | M8: View | N8: View | O8: Not applicable
A9: REQ-008 | B9: View | C9: View | D9: View | E9: View | F9: Manage | G9: View | H9: View | I9: View | J9: View | K9: Manage | L9: View | M9: Manage | N9: View | O9: Not applicable
A10: REQ-009 | B10: View | C10: View | D10: View | E10: View | F10: Control | G10: View | H10: View | I10: View | J10: View | K10: View | L10: View | M10: View | N10: View | O10: Not applicable
A11: REQ-010 | B11: View | C11: View | D11: View | E11: View | F11: Control | G11: View | H11: View | I11: View | J11: View | K11: View | L11: View | M11: Manage | N11: View | O11: Not applicable
A12: REQ-011 | B12: View | C12: View | D12: View | E12: View | F12: Control | G12: View | H12: View | I12: View | J12: View | K12: Manage | L12: View | M12: View | N12: View | O12: Not applicable
... A51: REQ-050 | B51: Not applicable | C51: Not applicable | D51: Not applicable | E51: Not applicable | F51: Not applicable | G51: Not applicable | H51: Not applicable | I51: Not applicable | J51: Not applicable | K51: Not applicable | L51: Not applicable | M51: Not applicable | N51: Not applicable | O51: Manage

Sheet Control Options
A1: Capability | B1: Options represented | C1: Treatment
A2: Application Links | B2: View | C2: Fixed at View in the 48 standard combinations
A3: Application SSO | B3: View | C3: Fixed at View in the 48 standard combinations
A4: Client Inquiry & Insights | B4: View | C4: Fixed at View in the 48 standard combinations
A5: Client Lifecycle Management | B5: View, Manage, Control, Process | C5: Varied in the 48 standard combinations
A6: Client Servicing | B6: View, Manage, Control | C6: Varied in the 48 standard combinations
A7: Data and Reporting | B7: View | C7: Fixed at View in the 48 standard combinations
A8: Fee Management | B8: View | C8: Fixed at View in the 48 standard combinations
A9: Investor Portal | B9: View | C9: Fixed at View in the 48 standard combinations
A10: Managed Portfolios | B10: View | C10: Fixed at View in the 48 standard combinations
A11: Order Management | B11: View, Manage | C11: Varied in the 48 standard combinations
A12: Reference Data | B12: View | C12: Fixed at View in the 48 standard combinations
... A15: User Access Management | B15: View, Manage | C15: Standalone and exclusive

Sheet Reference
A1: Product | B1: Control | D1: Feature control options
A2: Application Links | B2: View | D2: V
A3: Application SSO | B3: View | D3: V-O
A4: Client Inquiry & Insights | B4: View | D4: M
A5: Client Lifecycle Management | B5: View | D5: M-O
A6: Client Lifecycle Management | B6: Manage | D6: C
A7: Client Lifecycle Management | B7: Control | D7: C-O
A8: Client Lifecycle Management | B8: Process | D8: P
A9: Client Servicing | B9: View | D9: n/a
A10: Client Servicing | B10: Manage
A11: Client Servicing | B11: Control
A12: Client Servicing | B12: Process
A13: Data and Reporting | B13: View
A14: Fee Management | B14: View
A15: Investor Portal | B15: View
A16: Managed Portfolios | B16: View
A17: Order Management | B17: View
A18: Order Management | B18: Manage
A19: Reference Data | B19: View
A20: Trade Operations | B20: View
A21: Trade Operations | B21: Manage
... A25: User Access Management | B25: Manage
A30: Out of Scope - these are internal or apply to all users and don't need to be on UAR
A31: Product | B31: Control
A32: Application Status | B32: View
A33: Feature Management | B33: Manage
A34: Firm Configuration | B34: View
A35: Firm Configuration | B35: Manage
A36: User Communications | B36: View
A37: User Communications | B37: Manage
A38: User Content | B38: View
A39: User Settings | B39: View
A40: User Settings | B40: Manage

Sheet Full Map - OLD(98)
P1: Product | Q1: Client Inquiry & Insights | AG1: Investor Portal | AI1: Client Lifecycle Management | AT1: Client Servicing | BH1: Order Management | BQ1: Trade Operations | CH1: Trading Tools | CL1: Managed Portfolios | CM1: Data and Reporting | CQ1: Fee Management | CS1: Reference Data | CV1: User Access Management | DD1: Application Links | DG1: Application SSO
P2: Feature | Q2: Client & Account Summary | R2: Client Profile | S2: Client Profile | T2: Client Documents | U2: Account Profile | V2: Account Profile | W2: Account Holdings | X2: Account Activity | Y2: Account Profile | Z2: Account Profile | AA2: Account Documents | AB2: Account Documents | AC2: Account Documents | AD2: Account Documents | AE2: Account Documents | AF2: Client & Account Summary | AG2: Investor Portal Advisor View | AH2: Investor Portal Document Upload | AI2: Form-based Onboarding | AJ2: Paper Upload | AK2: CRS-FACTA Submissions | AL2: CRS-FACTA Submissions | AM2: Add Account | AN2: Client Profile Modifications | AO2: Client Profile Modifications | AP2: Estate Settlement | AQ2: Estate Settlement | AR2: Estate Settlement Resource | AS2: NBIN Document Resource Centre | AT2: Transfer Alerts | AU2: Transfer Statuses | AV2: Transfers Management | AW2: Transfers Management | AX2: Servicing | AY2: Servicing | AZ2: Systematic Plans | BA2: Systematic Plans | BB2: DRIP | BC2: Book Value Adjustments | BD2: Internal Transfers (Journals) | BE2: Tax Slip Events | BF2: Tax Slip Maintenance | BG2: Maturing Instruments | BH2: Core Orders Monitoring | BI2: Core Orders: Mutual Funds | BJ2: Core Orders: Equity | BK2: Core Orders: Options | BL2: Basket Orders | BM2: Basket Orders | BN2: GIC | BO2: New Issues | BP2: Equity Borrowing | BQ2: Trade Allocations | BR2: Trade Allocations | BS2: Trade Allocations | BT2: Trade Allocations | BU2: Trade Allocations | BV2: Trade Allocations | BW2: Option Expiry | BX2: Option Expiry | BY2: Options Commissions | BZ2: Options Email Delivery | CA2: Options Positions | CB2: Options Positions | CC2: View Re-Org Events | CD2: Re-Org Events | CE2: View Re-Org Events | CF2: Fund Facts | CG2: Fund Facts | CH2: NBF Research | CI2: NBF Research | CJ2: Evercore Research | CK2: Strucutred Products | CL2: Managed Portfolio Solutions | CM2: Credit Monitoring | CN2: Data Exports | CO2: Firm Reports | CP2: Firm Reports | CQ2: Management Fees Upload | CR2: Custody Fee Management | CS2: Historical FX Rates | CT2: Live Exchange Rates | CU2: Quotes | CV2: Client User Management | CW2: Global User Management | CX2: Global User Management | CY2: Global User Management | CZ2: Global User Management | DA2: Global User Management | DB2: Global User Management | DC2: Global User Management | DD2: Compass (Legacy) | DE2: Tools | DF2: NetRep | DG2: Creosus | DH2: D1G1T | DI2: Harmony
P3: Module | Q3: Accounts | R3: Client Accounts | S3: Client Profile | T3: Profile Documents | U3: Account Profile | V3: Accounts | W3: Positions | X3: Transactions | Y3: Accounts | Z3: Accounts | AA3: Statements | AB3: Tax Documents | AC3: Trade Confirmations | AD3: Securities Lending Reports | AE3: Estate Tax Slips | AF3: Activity Monitoring | AG3: My Portfolio+ IA | AH3: Bulk Document Upload | AI3: Form-Based Onboarding | AJ3: Paper Upload | AK3: CRS-FACTA Submissions | AL3: CRS-FACTA Submissions | AM3: Accounts | AN3: myRequest | AO3: TBC | AP3: Estate Settlement | AQ3: myRequest | AR3: Tools | AS3: Tools | AT3: Transfers Management | AU3: Transfers Management | AV3: Transfers Management | AW3: Transfers Management | AX3: Servicing | AY3: Servicing | AZ3: Systematic Plans (R2) | BA3: Systematic Plans | BB3: Tools | BC3: File Uploads | BD3: File Uploads | BE3: My Tax Slip Info | BF3: Tax Slip Maintenance & Notifications | BG3: Tools | BH3: Orders | BI3: Orders | BJ3: Orders | BK3: Orders | BL3: Basket Orders | BM3: File Uploads | BN3: GIC | BO3: Allocations | BP3: Tools | BQ3: MaxLite | BR3: Trade Allocations | BS3: Trade Allocations | BT3: Trade Allocation Approvals | BU3: Trade Allocation Processing | BV3: File Uploads | BW3: Option Expiry Events | BX3: Option Expiry Events (?) | BY3: Options Positions | BZ3: Options Positions | CA3: Options Positions | CB3: Options Management | CC3: Tools | CD3: File Uploads | CE3: Re-org Management | CF3: Fund Facts | CG3: Fund Facts | CH3: NBF Research | CI3: NBF Research | CJ3: Evercore Research | CK3: Trading Tools | CL3: Managed Portfolio Solutions | CM3: CRMA | CN3: Data Export | CO3: Firm Reporting | CP3: WebPanagon | CQ3: File Upload: Management Fees - Single/Batch | CR3: Fees | CS3: Tools | CT3: Tools | CU3: Tools | CV3: MyPortfolio+ User Admin | CW3: Users | CX3: Users | CY3: Users | CZ3: Users | DA3: Users | DB3: Manage Attestations | DC3: Manage Attestations | DD3: Compass (Legacy) | DE3: Application Links - E Trans (FIS) | DF3: Application Links - NetRep | DG3: Creosus | DH3: DIGIT | DI3: Harmony
P4: Module Resource | Q4: View Firm Client Accounts | R4: View Client Accounts | S4: View Client Profile | T4: Client Profile Documents | U4: View Account Profile | V4: Account Memos | W4: Positions | X4: Transactions | Y4: Account Fees | Z4: Fund Account Display | AA4: Statements | AB4: Tax Slips | AC4: Trade Confirmations | AD4: Securities Lending Reports | AE4: Estate Tax Slips | AF4: Activity Monitoring | AG4: Access My Portfolio+ IA | AH4: Access Bulk Document Upload | AI4: Form-based Onboarding | AJ4: Paper Upload | AK4: CRS-FATCA Submissions - View | AL4: CRS-FATCA Submissions - Manage | AM4: Add Account | AN4: MyRequest Banking & Address Updates | AO4: Client Profile Modifications | AP4: Estate Settlement | AQ4: Estate Settlement | AR4: Tools | AS4: NBIN Document Resource Centre | AT4: Transfer Alerts | AU4: Transfers statuses | AV4: Transfers | AW4: Transfers Management | AX4: Access Servicing | AY4: Access Servicing > Approvals | AZ4: Systematic Plans | BA4: Systematic Plans | BB4: Tools | BC4: File Upload: Book Value Updates | BD4: File Upload: Journal Processing | BE4: My Tax Slip Info | BF4: Tax Slip Maintenance & Notifications | BG4: Tools | BH4: Orders | BI4: Manage Mutual Fund Orders | BJ4: Manage Equity Orders | BK4: Manage Option Orders | BL4: Manage Basket Orders | BM4: Mutual Fund File Upload | BN4: Access GIC | BO4: Access New Issues | BP4: Tools | BQ4: Access Maxlite | BR4: View Trade Allocations | BS4: Manage Trade Allocations | BT4: Trade Allocation Approvals | BU4: Trade Allocation Processing | BV4: Trade Advice File Upload | BW4: Option Expiry Events | BX4: Option Expiry Events > Uploads | BY4: Tools - Options Commissions | BZ4: Tools - Options Email Delivery Log | CA4: Tools - Options Positions | CB4: Options Management TBC | CC4: Tools | CD4: Re-Org Events >. Uploads | CE4: Re-Org Events TBC | CF4: Access Send Fund Facts | CG4: Access Fund Facts History | CH4: NBF Research | CI4: NBF Research | CJ4: Evercore Research | CK4: Structured Products | CL4: Application Links - Managed Portfolio Solutions (MPS) | CM4: Access CRMA | CN4: Access Data Export | CO4: Access Firm Reporting | CP4: Access WebPanagon | CQ4: File Upload: Management Fees - Single/Batch | CR4: TBC | CS4: Tools | CT4: Tools - Live Exchange Rates | CU4: Delayed Quotes | CV4: Access MyPortfolio+ User Admin | CW4: Users | CX4: SSO Users | CY4: Users > Uploads | CZ4: Users > Exports | DA4: Tools - Manage Firm Users | DB4: Firm Attestations | DC4: Attestations | DD4: Compass (Legacy) | DE4: Application Links - E Trans (FIS) | DF4: Application Links - NetRep | DG4: Creosus | DH4: DIGIT | DI4: Harmony
A5: Requirement ID | B5: Application Links | C5: Application SSO | D5: Client Inquiry & Insights | E5: Client Lifecycle Management | F5: Client Servicing | G5: Data and Reporting | H5: Fee Management | I5: Investor Portal | J5: Managed Portfolios | K5: Order Management | L5: Reference Data | M5: Trade Operations | N5: Trading Tools | O5: User Access Management | P5: Role
A6: REQ-001 | B6: View | C6: View | D6: View | E6: View | F6: View | G6: View | H6: View | I6: View | J6: View | K6: View | L6: View | M6: View | N6: View | O6: Not applicable | P6: ViewOnlyConfidentialProfile_V1.17 | Q6: V | R6: V | S6: V | T6: V | U6: V | V6: V | W6: V | X6: V | Y6: V-O | Z6: V-O | AA6: V-O | AB6: V-O | AC6: V-O | AD6: V-O | AE6: V-O | AG6: V-O | AH6: V-O | AI6: V | AJ6: V | AK6: V-O | AL6: n/a | AM6: V | AN6: V | AO6: V | AQ6: V | AR6: V | AS6: V | AV6: V | AX6: V | AY6: n/a | AZ6: n/a | BB6: V | BC6: V-O | BD6: V-O | BE6: V | BF6: V | BH6: V | BP6: V | BQ6: V | BW6: V | BZ6: V | CA6: V | CB6: V | CC6: V | CE6: V | CH6: V-O | CJ6: V-O | CK6: V-O | CL6: V-O | CM6: V-O | CN6: V-O | CO6: V-O | CP6: V-O | CQ6: V-O | CS6: V | CT6: V | CU6: V | DD6: V-O | DE6: V-O | DF6: V-O | DG6: V-O | DH6: V-O | DI6: V-O
A7: REQ-002 | B7: View | C7: View | D7: View | E7: View | F7: View | G7: View | H7: View | I7: View | J7: View | K7: View | L7: View | M7: Manage | N7: View | O7: Not applicable | P7: No Role Available | Q7: V | R7: V | S7: V | T7: V | U7: V | V7: V | W7: V | X7: V | Y7: V-O | Z7: V-O | AA7: V-O | AB7: V-O | AC7: V-O | AD7: V-O | AE7: V-O | AG7: V-O | AH7: V-O | AI7: V | AJ7: V | AK7: V-O | AL7: n/a | AM7: V | AN7: V | AO7: V | AQ7: V | AR7: V | AS7: V | AV7: V | AX7: V | AY7: n/a | AZ7: n/a | BB7: V | BC7: V-O | BD7: V-O | BE7: V | BF7: V | BH7: V | BP7: V | BQ7: V | BR7: M | BS7: M | BW7: V | BX7: M | BY7: M | BZ7: V | CA7: V | CB7: M | CC7: V | CD7: M | CE7: V | CF7: M-O | CH7: V-O | CJ7: V-O | CK7: V-O | CL7: V-O | CM7: V-O | CN7: V-O | CO7: V-O | CP7: V-O | CQ7: V-O | CS7: V | CT7: V | CU7: V | DD7: V-O | DE7: V-O | DF7: V-O | DG7: V-O | DH7: V-O | DI7: V-O
A8: REQ-003 | B8: View | C8: View | D8: View | E8: View | F8: View | G8: View | H8: View | I8: View | J8: View | K8: View | L8: View | M8: Control | N8: View | O8: Not applicable | Q8: V | R8: V | S8: V | T8: V | U8: V | V8: V | W8: V | X8: V | Y8: V-O | Z8: V-O | AA8: V-O | AB8: V-O | AC8: V-O | AD8: V-O | AE8: V-O | AG8: V-O | AH8: V-O | AI8: V | AJ8: V | AK8: V-O | AL8: n/a | AM8: V | AN8: V | AO8: V | AQ8: V | AR8: V | AS8: V | AV8: V | AX8: V | AY8: n/a | AZ8: n/a | BB8: V | BC8: V-O | BD8: V-O | BE8: V | BF8: V | BH8: V | BP8: V | BQ8: V | BT8: C | BU8: C | BW8: V | BZ8: V | CA8: V | CC8: V | CE8: V | CH8: V-O | CJ8: V-O | CK8: V-O | CL8: V-O | CM8: V-O | CN8: V-O | CO8: V-O | CP8: V-O | CQ8: V-O | CS8: V | CT8: V | CU8: V | DD8: V-O | DE8: V-O | DF8: V-O | DG8: V-O | DH8: V-O | DI8: V-O
A9: REQ-004 | B9: View | C9: View | D9: View | E9: View | F9: View | G9: View | H9: View | I9: View | J9: View | K9: Manage | L9: View | M9: View | N9: View | O9: Not applicable | Q9: V | R9: V | S9: V | T9: V | U9: V | V9: V | W9: V | X9: V | Y9: V-O | Z9: V-O | AA9: V-O | AB9: V-O | AC9: V-O | AD9: V-O | AE9: V-O | AG9: V-O | AH9: V-O | AI9: V | AJ9: V | AK9: V-O | AL9: n/a | AM9: V | AN9: V | AO9: V | AQ9: V | AR9: V | AS9: V | AV9: V | AX9: V | AY9: n/a | AZ9: n/a | BB9: V | BC9: V-O | BD9: V-O | BE9: V | BF9: V | BH9: V | BI9: M-O | BJ9: M-O | BK9: M-O | BL9: M-O | BM9: M-O | BN9: M-O | BO9: M-O | BP9: V | BQ9: V | BW9: V | BZ9: V | CA9: V | CB9: V | CC9: V | CE9: V | CH9: V-O | CJ9: V-O | CK9: V-O | CL9: V-O | CM9: V-O | CN9: V-O | CO9: V-O | CP9: V-O | CQ9: V-O | CS9: V | CT9: V | CU9: V | DD9: V-O | DE9: V-O | DF9: V-O | DG9: V-O | DH9: V-O | DI9: V-O
A10: REQ-005 | B10: View | C10: View | D10: View | E10: View | F10: View | G10: View | H10: View | I10: View | J10: View | K10: Manage | L10: View | M10: Manage | N10: View | O10: Not applicable | Q10: V | R10: V | S10: V | T10: V | U10: V | V10: V | W10: V | X10: V | Y10: V-O | Z10: V-O | AA10: V-O | AB10: V-O | AC10: V-O | AD10: V-O | AE10: V-O | AG10: V-O | AH10: V-O | AI10: V | AJ10: V | AK10: V-O | AL10: n/a | AM10: V | AN10: V | AO10: V | AQ10: V | AR10: V | AS10: V | AV10: V | AX10: V | AY10: n/a | AZ10: n/a | BB10: V | BC10: V-O | BD10: V-O | BE10: V | BF10: V | BH10: V | BI10: M-O | BJ10: M-O | BK10: M-O | BL10: M-O | BM10: M-O | BN10: M-O | BO10: M-O | BP10: V | BQ10: V | BR10: M | BS10: M | BW10: V | BX10: M | BY10: M | BZ10: V | CA10: V | CB10: M | CC10: V | CD10: M | CE10: V | CF10: M-O | CH10: V-O | CJ10: V-O | CK10: V-O | CL10: V-O | CM10: V-O | CN10: V-O | CO10: V-O | CP10: V-O | CQ10: V-O | CS10: V | CT10: V | CU10: V | DD10: V-O | DE10: V-O | DF10: V-O | DG10: V-O | DH10: V-O | DI10: V-O
A11: REQ-006 | B11: View | C11: View | D11: View | E11: View | F11: View | G11: View | H11: View | I11: View | J11: View | K11: Manage | L11: View | M11: Control | N11: View | O11: Not applicable | Q11: V | R11: V | S11: V | T11: V | U11: V | V11: V | W11: V | X11: V | Y11: V-O | Z11: V-O | AA11: V-O | AB11: V-O | AC11: V-O | AD11: V-O | AE11: V-O | AG11: V-O | AH11: V-O | AI11: V | AJ11: V | AK11: V-O | AL11: n/a | AM11: V | AN11: V | AO11: V | AQ11: V | AR11: V | AS11: V | AV11: V | AX11: V | AY11: n/a | AZ11: n/a | BB11: V | BC11: V-O | BD11: V-O | BE11: V | BF11: V | BH11: V | BI11: M-O | BJ11: M-O | BK11: M-O | BL11: M-O | BM11: M-O | BN11: M-O | BO11: M-O | BP11: V | BQ11: V | BT11: C | BU11: C | BW11: V | BZ11: V | CA11: V | CC11: V | CE11: V | CH11: V-O | CJ11: V-O | CK11: V-O | CL11: V-O | CM11: V-O | CN11: V-O | CO11: V-O | CP11: V-O | CQ11: V-O | CS11: V | CT11: V | CU11: V | DD11: V-O | DE11: V-O | DF11: V-O | DG11: V-O | DH11: V-O | DI11: V-O
A12: REQ-007 | B12: View | C12: View | D12: View | E12: View | F12: Manage | G12: View | H12: View | I12: View | J12: View | K12: View | L12: View | M12: View | N12: View | O12: Not applicable | Q12: V | R12: V | S12: V | T12: V | U12: V | V12: V | W12: V | X12: V | Y12: V-O | Z12: V-O | AA12: V-O | AB12: V-O | AC12: V-O | AD12: V-O | AE12: V-O | AG12: V-O | AH12: V-O | AI12: V | AJ12: V | AK12: V-O | AL12: n/a | AM12: V | AN12: V | AO12: V | AQ12: V | AR12: V | AS12: V | AV12: M | AX12: M | AY12: n/a | AZ12: M | BB12: V | BC12: M-O | BD12: M-O | BE12: V | BF12: V | BH12: V | BP12: V | BQ12: V | BW12: V | BZ12: V | CA12: V | CB12: V | CC12: V | CE12: V | CH12: V-O | CJ12: V-O | CK12: V-O | CL12: V-O | CM12: V-O | CN12: V-O | CO12: V-O | CP12: V-O | CQ12: V-O | CS12: V | CT12: V | CU12: V | DD12: V-O | DE12: V-O | DF12: V-O | DG12: V-O | DH12: V-O | DI12: V-O
A13: REQ-008 | B13: View | C13: View | D13: View | E13: View | F13: Manage | G13: View | H13: View | I13: View | J13: View | K13: View | L13: View | M13: Manage | N13: View | O13: Not applicable | Q13: V | R13: V | S13: V | T13: V | U13: V | V13: V | W13: V | X13: V | Y13: V-O | Z13: V-O | AA13: V-O | AB13: V-O | AC13: V-O | AD13: V-O | AE13: V-O | AG13: V-O | AH13: V-O | AI13: V | AJ13: V | AK13: V-O | AL13: n/a | AM13: V | AN13: V | AO13: V | AQ13: V | AR13: V | AS13: V | AV13: M | AX13: M | AY13: n/a | AZ13: M | BB13: V | BC13: M-O | BD13: M-O | BE13: V | BF13: V | BH13: V | BP13: V | BQ13: V | BR13: M | BS13: M | BW13: V | BX13: M | BY13: M | BZ13: V | CA13: V | CB13: M | CC13: V | CD13: M | CE13: V | CF13: M-O | CH13: V-O | CJ13: V-O | CK13: V-O | CL13: V-O | CM13: V-O | CN13: V-O | CO13: V-O | CP13: V-O | CQ13: V-O | CS13: V | CT13: V | CU13: V | DD13: V-O | DE13: V-O | DF13: V-O | DG13: V-O | DH13: V-O | DI13: V-O
A14: REQ-009 | B14: View | C14: View | D14: View | E14: View | F14: Manage | G14: View | H14: View | I14: View | J14: View | K14: View | L14: View | M14: Control | N14: View | O14: Not applicable | Q14: V | R14: V | S14: V | T14: V | U14: V | V14: V | W14: V | X14: V | Y14: V-O | Z14: V-O | AA14: V-O | AB14: V-O | AC14: V-O | AD14: V-O | AE14: V-O | AG14: V-O | AH14: V-O | AI14: V | AJ14: V | AK14: V-O | AL14: n/a | AM14: V | AN14: V | AO14: V | AQ14: V | AR14: V | AS14: V | AV14: M | AX14: M | AY14: n/a | AZ14: M | BB14: V | BC14: M-O | BD14: M-O | BE14: V | BF14: V | BH14: V | BP14: V | BQ14: V | BT14: C | BU14: C | BW14: V | BZ14: V | CA14: V | CC14: V | CE14: V | CH14: V-O | CJ14: V-O | CK14: V-O | CL14: V-O | CM14: V-O | CN14: V-O | CO14: V-O | CP14: V-O | CQ14: V-O | CS14: V | CT14: V | CU14: V | DD14: V-O | DE14: V-O | DF14: V-O | DG14: V-O | DH14: V-O | DI14: V-O
A15: REQ-010 | B15: View | C15: View | D15: View | E15: View | F15: Manage | G15: View | H15: View | I15: View | J15: View | K15: Manage | L15: View | M15: View | N15: View | O15: Not applicable | Q15: V | R15: V | S15: V | T15: V | U15: V | V15: V | W15: V | X15: V | Y15: V-O | Z15: V-O | AA15: V-O | AB15: V-O | AC15: V-O | AD15: V-O | AE15: V-O | AG15: V-O | AH15: V-O | AI15: V | AJ15: V | AK15: V-O | AL15: n/a | AM15: V | AN15: V | AO15: V | AQ15: V | AR15: V | AS15: V | AV15: M | AX15: M | AY15: n/a | AZ15: M | BB15: V | BC15: M-O | BD15: M-O | BE15: V | BF15: V | BH15: V | BI15: M-O | BJ15: M-O | BK15: M-O | BL15: M-O | BM15: M-O | BN15: M-O | BO15: M-O | BP15: V | BQ15: V | BW15: V | BZ15: V | CA15: V | CB15: V | CC15: V | CE15: V | CH15: V-O | CJ15: V-O | CK15: V-O | CL15: V-O | CM15: V-O | CN15: V-O | CO15: V-O | CP15: V-O | CQ15: V-O | CS15: V | CT15: V | CU15: V | DD15: V-O | DE15: V-O | DF15: V-O | DG15: V-O | DH15: V-O | DI15: V-O
A16: REQ-011 | B16: View | C16: View | D16: View | E16: View | F16: Manage | G16: View | H16: View | I16: View | J16: View | K16: Manage | L16: View | M16: Manage | N16: View | O16: Not applicable | Q16: V | R16: V | S16: V | T16: V | U16: V | V16: V | W16: V | X16: V | Y16: V-O | Z16: V-O | AA16: V-O | AB16: V-O | AC16: V-O | AD16: V-O | AE16: V-O | AG16: V-O | AH16: V-O | AI16: V | AJ16: V | AK16: V-O | AL16: n/a | AM16: V | AN16: V | AO16: V | AQ16: V | AR16: V | AS16: V | AV16: M | AX16: M | AY16: n/a | AZ16: M | BB16: V | BC16: M-O | BD16: M-O | BE16: V | BF16: V | BH16: V | BI16: M-O | BJ16: M-O | BK16: M-O | BL16: M-O | BM16: M-O | BN16: M-O | BO16: M-O | BP16: V | BQ16: V | BR16: M | BS16: M | BW16: V | BX16: M | BY16: M | BZ16: V | CA16: V | CB16: M | CC16: V | CD16: M | CE16: V | CF16: M-O | CH16: V-O | CJ16: V-O | CK16: V-O | CL16: V-O | CM16: V-O | CN16: V-O | CO16: V-O | CP16: V-O | CQ16: V-O | CS16: V | CT16: V | CU16: V | DD16: V-O | DE16: V-O | DF16: V-O | DG16: V-O | DH16: V-O | DI16: V-O
A17: REQ-012 | B17: View | C17: View | D17: View | E17: View | F17: Manage | G17: View | H17: View | I17: View | J17: View | K17: Manage | L17: View | M17: Control | N17: View | O17: Not applicable | Q17: V | R17: V | S17: V | T17: V | U17: V | V17: V | W17: V | X17: V | Y17: V-O | Z17: V-O | AA17: V-O | AB17: V-O | AC17: V-O | AD17: V-O | AE17: V-O | AG17: V-O | AH17: V-O | AI17: V | AJ17: V | AK17: V-O | AL17: n/a | AM17: V | AN17: V | AO17: V | AQ17: V | AR17: V | AS17: V | AV17: M | AX17: M | AY17: n/a | AZ17: M | BB17: V | BC17: M-O | BD17: M-O | BE17: V | BF17: V | BH17: V | BI17: M-O | BJ17: M-O | BK17: M-O | BL17: M-O | BM17: M-O | BN17: M-O | BO17: M-O | BP17: V | BQ17: V | BT17: C | BU17: C | BW17: V | BZ17: V | CA17: V | CC17: V | CE17: V | CH17: V-O | CJ17: V-O | CK17: V-O | CL17: V-O | CM17: V-O | CN17: V-O | CO17: V-O | CP17: V-O | CQ17: V-O | CS17: V | CT17: V | CU17: V | DD17: V-O | DE17: V-O | DF17: V-O | DG17: V-O | DH17: V-O | DI17: V-O
A18: REQ-013 | B18: View | C18: View | D18: View | E18: View | F18: Control | G18: View | H18: View | I18: View | J18: View | K18: View | L18: View | M18: View | N18: View | O18: Not applicable | Q18: V | R18: V | S18: V | T18: V | U18: V | V18: V | W18: V | X18: V | Y18: V-O | Z18: V-O | AA18: V-O | AB18: V-O | AC18: V-O | AD18: V-O | AE18: V-O | AG18: V-O | AH18: V-O | AI18: V | AJ18: V | AK18: V-O | AL18: n/a | AM18: V | AN18: V | AO18: V | AQ18: V | AR18: V | AS18: V | AX18: M | AY18: C | BB18: V | BE18: V | BF18: V | BH18: V | BP18: V | BQ18: V | BW18: V | BZ18: V | CA18: V | CB18: V | CC18: V | CE18: V | CH18: V-O | CJ18: V-O | CK18: V-O | CL18: V-O | CM18: V-O | CN18: V-O | CO18: V-O | CP18: V-O | CQ18: V-O | CS18: V | CT18: V | CU18: V | DD18: V-O | DE18: V-O | DF18: V-O | DG18: V-O | DH18: V-O | DI18: V-O
A19: REQ-014 | B19: View | C19: View | D19: View | E19: View | F19: Control | G19: View | H19: View | I19: View | J19: View | K19: View | L19: View | M19: Manage | N19: View | O19: Not applicable | Q19: V | R19: V | S19: V | T19: V | U19: V | V19: V | W19: V | X19: V | Y19: V-O | Z19: V-O | AA19: V-O | AB19: V-O | AC19: V-O | AD19: V-O | AE19: V-O | AG19: V-O | AH19: V-O | AI19: V | AJ19: V | AK19: V-O | AL19: n/a | AM19: V | AN19: V | AO19: V | AQ19: V | AR19: V | AS19: V | AX19: M | AY19: C | BB19: V | BE19: V | BF19: V | BH19: V | BP19: V | BQ19: V | BR19: M | BS19: M | BW19: V | BX19: M | BY19: M | BZ19: V | CA19: V | CB19: M | CC19: V | CD19: M | CE19: V | CF19: M-O | CH19: V-O | CJ19: V-O | CK19: V-O | CL19: V-O | CM19: V-O | CN19: V-O | CO19: V-O | CP19: V-O | CQ19: V-O | CS19: V | CT19: V | CU19: V | DD19: V-O | DE19: V-O | DF19: V-O | DG19: V-O | DH19: V-O | DI19: V-O
A20: REQ-015 | B20: View | C20: View | D20: View | E20: View | F20: Control | G20: View | H20: View | I20: View | J20: View | K20: View | L20: View | M20: Control | N20: View | O20: Not applicable | Q20: V | R20: V | S20: V | T20: V | U20: V | V20: V | W20: V | X20: V | Y20: V-O | Z20: V-O | AA20: V-O | AB20: V-O | AC20: V-O | AD20: V-O | AE20: V-O | AG20: V-O | AH20: V-O | AI20: V | AJ20: V | AK20: V-O | AL20: n/a | AM20: V | AN20: V | AO20: V | AQ20: V | AR20: V | AS20: V | AX20: M | AY20: C | BB20: V | BE20: V | BF20: V | BH20: V | BP20: V | BQ20: V | BT20: C | BU20: C | BW20: V | BZ20: V | CA20: V | CC20: V | CE20: V | CH20: V-O | CJ20: V-O | CK20: V-O | CL20: V-O | CM20: V-O | CN20: V-O | CO20: V-O | CP20: V-O | CQ20: V-O | CS20: V | CT20: V | CU20: V | DD20: V-O | DE20: V-O | DF20: V-O | DG20: V-O | DH20: V-O | DI20: V-O
A21: REQ-016 | B21: View | C21: View | D21: View | E21: View | F21: Control | G21: View | H21: View | I21: View | J21: View | K21: Manage | L21: View | M21: View | N21: View | O21: Not applicable | Q21: V | R21: V | S21: V | T21: V | U21: V | V21: V | W21: V | X21: V | Y21: V-O | Z21: V-O | AA21: V-O | AB21: V-O | AC21: V-O | AD21: V-O | AE21: V-O | AG21: V-O | AH21: V-O | AI21: V | AJ21: V | AK21: V-O | AL21: n/a | AM21: V | AN21: V | AO21: V | AQ21: V | AR21: V | AS21: V | AX21: M | AY21: C | BB21: V | BE21: V | BF21: V | BH21: V | BI21: M-O | BJ21: M-O | BK21: M-O | BL21: M-O | BM21: M-O | BN21: M-O | BO21: M-O | BP21: V | BQ21: V | BW21: V | BZ21: V | CA21: V | CB21: V | CC21: V | CE21: V | CH21: V-O | CJ21: V-O | CK21: V-O | CL21: V-O | CM21: V-O | CN21: V-O | CO21: V-O | CP21: V-O | CQ21: V-O | CS21: V | CT21: V | CU21: V | DD21: V-O | DE21: V-O | DF21: V-O | DG21: V-O | DH21: V-O | DI21: V-O
A22: REQ-017 | B22: View | C22: View | D22: View | E22: View | F22: Control | G22: View | H22: View | I22: View | J22: View | K22: Manage | L22: View | M22: Manage | N22: View | O22: Not applicable | Q22: V | R22: V | S22: V | T22: V | U22: V | V22: V | W22: V | X22: V | Y22: V-O | Z22: V-O | AA22: V-O | AB22: V-O | AC22: V-O | AD22: V-O | AE22: V-O | AG22: V-O | AH22: V-O | AI22: V | AJ22: V | AK22: V-O | AL22: n/a | AM22: V | AN22: V | AO22: V | AQ22: V | AR22: V | AS22: V | AX22: M | AY22: C | BB22: V | BE22: V | BF22: V | BH22: V | BI22: M-O | BJ22: M-O | BK22: M-O | BL22: M-O | BM22: M-O | BN22: M-O | BO22: M-O | BP22: V | BQ22: V | BR22: M | BS22: M | BW22: V | BX22: M | BY22: M | BZ22: V | CA22: V | CB22: M | CC22: V | CD22: M | CE22: V | CF22: M-O | CH22: V-O | CJ22: V-O | CK22: V-O | CL22: V-O | CM22: V-O | CN22: V-O | CO22: V-O | CP22: V-O | CQ22: V-O | CS22: V | CT22: V | CU22: V | DD22: V-O | DE22: V-O | DF22: V-O | DG22: V-O | DH22: V-O | DI22: V-O
A23: REQ-018 | B23: View | C23: View | D23: View | E23: View | F23: Control | G23: View | H23: View | I23: View | J23: View | K23: Manage | L23: View | M23: Control | N23: View | O23: Not applicable | Q23: V | R23: V | S23: V | T23: V | U23: V | V23: V | W23: V | X23: V | Y23: V-O | Z23: V-O | AA23: V-O | AB23: V-O | AC23: V-O | AD23: V-O | AE23: V-O | AG23: V-O | AH23: V-O | AI23: V | AJ23: V | AK23: V-O | AL23: n/a | AM23: V | AN23: V | AO23: V | AQ23: V | AR23: V | AS23: V | AX23: M | AY23: C | BB23: V | BE23: V | BF23: V | BH23: V | BI23: M-O | BJ23: M-O | BK23: M-O | BL23: M-O | BM23: M-O | BN23: M-O | BO23: M-O | BP23: V | BQ23: V | BT23: C | BU23: C | BW23: V | BZ23: V | CA23: V | CC23: V | CE23: V | CH23: V-O | CJ23: V-O | CK23: V-O | CL23: V-O | CM23: V-O | CN23: V-O | CO23: V-O | CP23: V-O | CQ23: V-O | CS23: V | CT23: V | CU23: V | DD23: V-O | DE23: V-O | DF23: V-O | DG23: V-O | DH23: V-O | DI23: V-O
A24: REQ-019 | B24: View | C24: View | D24: View | E24: View | F24: Process | G24: View | H24: View | I24: View | J24: View | K24: View | L24: View | M24: View | N24: View | O24: Not applicable | Q24: V | R24: V | S24: V | T24: V | U24: V | V24: V | W24: V | X24: V | Y24: V-O | Z24: V-O | AA24: V-O | AB24: V-O | AC24: V-O | AD24: V-O | AE24: V-O | AG24: V-O | AH24: V-O | AI24: V | AJ24: V | AK24: V-O | AL24: n/a | AM24: V | AN24: V | AO24: V | AQ24: V | AR24: V | AS24: V | AX24: n/a | AY24: n/a | BB24: V | BE24: V | BF24: V | BH24: V | BP24: V | BQ24: V | BW24: V | BZ24: V | CA24: V | CB24: V | CC24: V | CE24: V | CH24: V-O | CJ24: V-O | CK24: V-O | CL24: V-O | CM24: V-O | CN24: V-O | CO24: V-O | CP24: V-O | CQ24: V-O | CS24: V | CT24: V | CU24: V | DD24: V-O | DE24: V-O | DF24: V-O | DG24: V-O | DH24: V-O | DI24: V-O
A25: REQ-020 | B25: View | C25: View | D25: View | E25: View | F25: Process | G25: View | H25: View | I25: View | J25: View | K25: View | L25: View | M25: Manage | N25: View | O25: Not applicable | Q25: V | R25: V | S25: V | T25: V | U25: V | V25: V | W25: V | X25: V | Y25: V-O | Z25: V-O | AA25: V-O | AB25: V-O | AC25: V-O | AD25: V-O | AE25: V-O | AG25: V-O | AH25: V-O | AI25: V | AJ25: V | AK25: V-O | AL25: n/a | AM25: V | AN25: V | AO25: V | AQ25: V | AR25: V | AS25: V | AX25: n/a | AY25: n/a | BB25: V | BE25: V | BF25: V | BH25: V | BP25: V | BQ25: V | BR25: M | BS25: M | BW25: V | BX25: M | BY25: M | BZ25: V | CA25: V | CB25: M | CC25: V | CD25: M | CE25: V | CF25: M-O | CH25: V-O | CJ25: V-O | CK25: V-O | CL25: V-O | CM25: V-O | CN25: V-O | CO25: V-O | CP25: V-O | CQ25: V-O | CS25: V | CT25: V | CU25: V | DD25: V-O | DE25: V-O | DF25: V-O | DG25: V-O | DH25: V-O | DI25: V-O
A26: REQ-021 | B26: View | C26: View | D26: View | E26: View | F26: Process | G26: View | H26: View | I26: View | J26: View | K26: View | L26: View | M26: Control | N26: View | O26: Not applicable | Q26: V | R26: V | S26: V | T26: V | U26: V | V26: V | W26: V | X26: V | Y26: V-O | Z26: V-O | AA26: V-O | AB26: V-O | AC26: V-O | AD26: V-O | AE26: V-O | AG26: V-O | AH26: V-O | AI26: V | AJ26: V | AK26: V-O | AL26: n/a | AM26: V | AN26: V | AO26: V | AQ26: V | AR26: V | AS26: V | AX26: n/a | AY26: n/a | BB26: V | BE26: V | BF26: V | BH26: V | BP26: V | BQ26: V | BT26: C | BU26: C | BW26: V | BZ26: V | CA26: V | CC26: V | CE26: V | CH26: V-O | CJ26: V-O | CK26: V-O | CL26: V-O | CM26: V-O | CN26: V-O | CO26: V-O | CP26: V-O | CQ26: V-O | CS26: V | CT26: V | CU26: V | DD26: V-O | DE26: V-O | DF26: V-O | DG26: V-O | DH26: V-O | DI26: V-O
A27: REQ-022 | B27: View | C27: View | D27: View | E27: View | F27: Process | G27: View | H27: View | I27: View | J27: View | K27: Manage | L27: View | M27: View | N27: View | O27: Not applicable | Q27: V | R27: V | S27: V | T27: V | U27: V | V27: V | W27: V | X27: V | Y27: V-O | Z27: V-O | AA27: V-O | AB27: V-O | AC27: V-O | AD27: V-O | AE27: V-O | AG27: V-O | AH27: V-O | AI27: V | AJ27: V | AK27: V-O | AL27: n/a | AM27: V | AN27: V | AO27: V | AQ27: V | AR27: V | AS27: V | AX27: n/a | AY27: n/a | BB27: V | BE27: V | BF27: V | BH27: V | BI27: M-O | BJ27: M-O | BK27: M-O | BL27: M-O | BM27: M-O | BN27: M-O | BO27: M-O | BP27: V | BQ27: V | BW27: V | BZ27: V | CA27: V | CB27: V | CC27: V | CE27: V | CH27: V-O | CJ27: V-O | CK27: V-O | CL27: V-O | CM27: V-O | CN27: V-O | CO27: V-O | CP27: V-O | CQ27: V-O | CS27: V | CT27: V | CU27: V | DD27: V-O | DE27: V-O | DF27: V-O | DG27: V-O | DH27: V-O | DI27: V-O
A28: REQ-023 | B28: View | C28: View | D28: View | E28: View | F28: Process | G28: View | H28: View | I28: View | J28: View | K28: Manage | L28: View | M28: Manage | N28: View | O28: Not applicable | Q28: V | R28: V | S28: V | T28: V | U28: V | V28: V | W28: V | X28: V | Y28: V-O | Z28: V-O | AA28: V-O | AB28: V-O | AC28: V-O | AD28: V-O | AE28: V-O | AG28: V-O | AH28: V-O | AI28: V | AJ28: V | AK28: V-O | AL28: n/a | AM28: V | AN28: V | AO28: V | AQ28: V | AR28: V | AS28: V | AX28: n/a | AY28: n/a | BB28: V | BE28: V | BF28: V | BH28: V | BI28: M-O | BJ28: M-O | BK28: M-O | BL28: M-O | BM28: M-O | BN28: M-O | BO28: M-O | BP28: V | BQ28: V | BR28: M | BS28: M | BW28: V | BX28: M | BY28: M | BZ28: V | CA28: V | CB28: M | CC28: V | CD28: M | CE28: V | CF28: M-O | CH28: V-O | CJ28: V-O | CK28: V-O | CL28: V-O | CM28: V-O | CN28: V-O | CO28: V-O | CP28: V-O | CQ28: V-O | CS28: V | CT28: V | CU28: V | DD28: V-O | DE28: V-O | DF28: V-O | DG28: V-O | DH28: V-O | DI28: V-O
A29: REQ-024 | B29: View | C29: View | D29: View | E29: View | F29: Process | G29: View | H29: View | I29: View | J29: View | K29: Manage | L29: View | M29: Control | N29: View | O29: Not applicable | Q29: V | R29: V | S29: V | T29: V | U29: V | V29: V | W29: V | X29: V | Y29: V-O | Z29: V-O | AA29: V-O | AB29: V-O | AC29: V-O | AD29: V-O | AE29: V-O | AG29: V-O | AH29: V-O | AI29: V | AJ29: V | AK29: V-O | AL29: n/a | AM29: V | AN29: V | AO29: V | AQ29: V | AR29: V | AS29: V | AX29: n/a | AY29: n/a | BB29: V | BE29: V | BF29: V | BH29: V | BI29: M-O | BJ29: M-O | BK29: M-O | BL29: M-O | BM29: M-O | BN29: M-O | BO29: M-O | BP29: V | BQ29: V | BT29: C | BU29: C | BW29: V | BZ29: V | CA29: V | CC29: V | CE29: V | CH29: V-O | CJ29: V-O | CK29: V-O | CL29: V-O | CM29: V-O | CN29: V-O | CO29: V-O | CP29: V-O | CQ29: V-O | CS29: V | CT29: V | CU29: V | DD29: V-O | DE29: V-O | DF29: V-O | DG29: V-O | DH29: V-O | DI29: V-O
A30: REQ-025 | B30: View | C30: View | D30: View | E30: Manage | F30: View | G30: View | H30: View | I30: View | J30: View | K30: View | L30: View | M30: View | N30: View | O30: Not applicable | Q30: V | R30: V | S30: V | T30: V | U30: V | V30: V | W30: V | X30: V | Y30: V-O | Z30: V-O | AA30: V-O | AB30: V-O | AC30: V-O | AD30: V-O | AE30: V-O | AG30: V-O | AH30: V-O | AI30: M | AJ30: M | AK30: V-O | AL30: M-O | AM30: M | AN30: M | AO30: M | AQ30: M | AR30: V | AS30: V | AV30: V | AX30: V | AY30: n/a | AZ30: n/a | BB30: V | BC30: V-O | BD30: V-O | BE30: V | BF30: V | BH30: V | BP30: V | BQ30: V | BW30: V | BZ30: V | CA30: V | CB30: V | CC30: V | CE30: V | CH30: V-O | CJ30: V-O | CK30: V-O | CL30: V-O | CM30: V-O | CN30: V-O | CO30: V-O | CP30: V-O | CQ30: V-O | CS30: V | CT30: V | CU30: V | DD30: V-O | DE30: V-O | DF30: V-O | DG30: V-O | DH30: V-O | DI30: V-O
A31: REQ-026 | B31: View | C31: View | D31: View | E31: Manage | F31: View | G31: View | H31: View | I31: View | J31: View | K31: View | L31: View | M31: Manage | N31: View | O31: Not applicable | Q31: V | R31: V | S31: V | T31: V | U31: V | V31: V | W31: V | X31: V | Y31: V-O | Z31: V-O | AA31: V-O | AB31: V-O | AC31: V-O | AD31: V-O | AE31: V-O | AG31: V-O | AH31: V-O | AI31: M | AJ31: M | AK31: V-O | AL31: M-O | AM31: M | AN31: M | AO31: M | AQ31: M | AR31: V | AS31: V | AV31: V | AX31: V | AY31: n/a | AZ31: n/a | BB31: V | BC31: V-O | BD31: V-O | BE31: V | BF31: V | BH31: V | BP31: V | BQ31: V | BR31: M | BS31: M | BW31: V | BX31: M | BY31: M | BZ31: V | CA31: V | CB31: M | CC31: V | CD31: M | CE31: V | CF31: M-O | CH31: V-O | CJ31: V-O | CK31: V-O | CL31: V-O | CM31: V-O | CN31: V-O | CO31: V-O | CP31: V-O | CQ31: V-O | CS31: V | CT31: V | CU31: V | DD31: V-O | DE31: V-O | DF31: V-O | DG31: V-O | DH31: V-O | DI31: V-O
A32: REQ-027 | B32: View | C32: View | D32: View | E32: Manage | F32: View | G32: View | H32: View | I32: View | J32: View | K32: View | L32: View | M32: Control | N32: View | O32: Not applicable | Q32: V | R32: V | S32: V | T32: V | U32: V | V32: V | W32: V | X32: V | Y32: V-O | Z32: V-O | AA32: V-O | AB32: V-O | AC32: V-O | AD32: V-O | AE32: V-O | AG32: V-O | AH32: V-O | AI32: M | AJ32: M | AK32: V-O | AL32: M-O | AM32: M | AN32: M | AO32: M | AQ32: M | AR32: V | AS32: V | AV32: V | AX32: V | AY32: n/a | AZ32: n/a | BB32: V | BC32: V-O | BD32: V-O | BE32: V | BF32: V | BH32: V | BP32: V | BQ32: V | BT32: C | BU32: C | BW32: V | BZ32: V | CA32: V | CC32: V | CE32: V | CH32: V-O | CJ32: V-O | CK32: V-O | CL32: V-O | CM32: V-O | CN32: V-O | CO32: V-O | CP32: V-O | CQ32: V-O | CS32: V | CT32: V | CU32: V | DD32: V-O | DE32: V-O | DF32: V-O | DG32: V-O | DH32: V-O | DI32: V-O
A33: REQ-028 | B33: View | C33: View | D33: View | E33: Manage | F33: View | G33: View | H33: View | I33: View | J33: View | K33: Manage | L33: View | M33: View | N33: View | O33: Not applicable | Q33: V | R33: V | S33: V | T33: V | U33: V | V33: V | W33: V | X33: V | Y33: V-O | Z33: V-O | AA33: V-O | AB33: V-O | AC33: V-O | AD33: V-O | AE33: V-O | AG33: V-O | AH33: V-O | AI33: M | AJ33: M | AK33: V-O | AL33: M-O | AM33: M | AN33: M | AO33: M | AQ33: M | AR33: V | AS33: V | AV33: V | AX33: V | AY33: n/a | AZ33: n/a | BB33: V | BC33: V-O | BD33: V-O | BE33: V | BF33: V | BH33: V | BI33: M-O | BJ33: M-O | BK33: M-O | BL33: M-O | BM33: M-O | BN33: M-O | BO33: M-O | BP33: V | BQ33: V | BW33: V | BZ33: V | CA33: V | CB33: V | CC33: V | CE33: V | CH33: V-O | CJ33: V-O | CK33: V-O | CL33: V-O | CM33: V-O | CN33: V-O | CO33: V-O | CP33: V-O | CQ33: V-O | CS33: V | CT33: V | CU33: V | DD33: V-O | DE33: V-O | DF33: V-O | DG33: V-O | DH33: V-O | DI33: V-O
A34: REQ-029 | B34: View | C34: View | D34: View | E34: Manage | F34: View | G34: View | H34: View | I34: View | J34: View | K34: Manage | L34: View | M34: Manage | N34: View | O34: Not applicable | Q34: V | R34: V | S34: V | T34: V | U34: V | V34: V | W34: V | X34: V | Y34: V-O | Z34: V-O | AA34: V-O | AB34: V-O | AC34: V-O | AD34: V-O | AE34: V-O | AG34: V-O | AH34: V-O | AI34: M | AJ34: M | AK34: V-O | AL34: M-O | AM34: M | AN34: M | AO34: M | AQ34: M | AR34: V | AS34: V | AV34: V | AX34: V | AY34: n/a | AZ34: n/a | BB34: V | BC34: V-O | BD34: V-O | BE34: V | BF34: V | BH34: V | BI34: M-O | BJ34: M-O | BK34: M-O | BL34: M-O | BM34: M-O | BN34: M-O | BO34: M-O | BP34: V | BQ34: V | BR34: M | BS34: M | BW34: V | BX34: M | BY34: M | BZ34: V | CA34: V | CB34: M | CC34: V | CD34: M | CE34: V | CF34: M-O | CH34: V-O | CJ34: V-O | CK34: V-O | CL34: V-O | CM34: V-O | CN34: V-O | CO34: V-O | CP34: V-O | CQ34: V-O | CS34: V | CT34: V | CU34: V | DD34: V-O | DE34: V-O | DF34: V-O | DG34: V-O | DH34: V-O | DI34: V-O
A35: REQ-030 | B35: View | C35: View | D35: View | E35: Manage | F35: View | G35: View | H35: View | I35: View | J35: View | K35: Manage | L35: View | M35: Control | N35: View | O35: Not applicable | Q35: V | R35: V | S35: V | T35: V | U35: V | V35: V | W35: V | X35: V | Y35: V-O | Z35: V-O | AA35: V-O | AB35: V-O | AC35: V-O | AD35: V-O | AE35: V-O | AG35: V-O | AH35: V-O | AI35: M | AJ35: M | AK35: V-O | AL35: M-O | AM35: M | AN35: M | AO35: M | AQ35: M | AR35: V | AS35: V | AV35: V | AX35: V | AY35: n/a | AZ35: n/a | BB35: V | BC35: V-O | BD35: V-O | BE35: V | BF35: V | BH35: V | BI35: M-O | BJ35: M-O | BK35: M-O | BL35: M-O | BM35: M-O | BN35: M-O | BO35: M-O | BP35: V | BQ35: V | BT35: C | BU35: C | BW35: V | BZ35: V | CA35: V | CC35: V | CE35: V | CH35: V-O | CJ35: V-O | CK35: V-O | CL35: V-O | CM35: V-O | CN35: V-O | CO35: V-O | CP35: V-O | CQ35: V-O | CS35: V | CT35: V | CU35: V | DD35: V-O | DE35: V-O | DF35: V-O | DG35: V-O | DH35: V-O | DI35: V-O
A36: REQ-031 | B36: View | C36: View | D36: View | E36: Manage | F36: Manage | G36: View | H36: View | I36: View | J36: View | K36: View | L36: View | M36: View | N36: View | O36: Not applicable | Q36: V | R36: V | S36: V | T36: V | U36: V | V36: V | W36: V | X36: V | Y36: V-O | Z36: V-O | AA36: V-O | AB36: V-O | AC36: V-O | AD36: V-O | AE36: V-O | AG36: V-O | AH36: V-O | AI36: M | AJ36: M | AK36: V-O | AL36: M-O | AM36: M | AN36: M | AO36: M | AQ36: M | AR36: V | AS36: V | AV36: M | AX36: M | AY36: n/a | AZ36: M | BB36: V | BC36: M-O | BD36: M-O | BE36: V | BF36: V | BH36: V | BP36: V | BQ36: V | BW36: V | BZ36: V | CA36: V | CB36: V | CC36: V | CE36: V | CH36: V-O | CJ36: V-O | CK36: V-O | CL36: V-O | CM36: V-O | CN36: V-O | CO36: V-O | CP36: V-O | CQ36: V-O | CS36: V | CT36: V | CU36: V | DD36: V-O | DE36: V-O | DF36: V-O | DG36: V-O | DH36: V-O | DI36: V-O
A37: REQ-032 | B37: View | C37: View | D37: View | E37: Manage | F37: Manage | G37: View | H37: View | I37: View | J37: View | K37: View | L37: View | M37: Manage | N37: View | O37: Not applicable | Q37: V | R37: V | S37: V | T37: V | U37: V | V37: V | W37: V | X37: V | Y37: V-O | Z37: V-O | AA37: V-O | AB37: V-O | AC37: V-O | AD37: V-O | AE37: V-O | AG37: V-O | AH37: V-O | AI37: M | AJ37: M | AK37: V-O | AL37: M-O | AM37: M | AN37: M | AO37: M | AQ37: M | AR37: V | AS37: V | AV37: M | AX37: M | AY37: n/a | AZ37: M | BB37: V | BC37: M-O | BD37: M-O | BE37: V | BF37: V | BH37: V | BP37: V | BQ37: V | BR37: M | BS37: M | BW37: V | BX37: M | BY37: M | BZ37: V | CA37: V | CB37: M | CC37: V | CD37: M | CE37: V | CF37: M-O | CH37: V-O | CJ37: V-O | CK37: V-O | CL37: V-O | CM37: V-O | CN37: V-O | CO37: V-O | CP37: V-O | CQ37: V-O | CS37: V | CT37: V | CU37: V | DD37: V-O | DE37: V-O | DF37: V-O | DG37: V-O | DH37: V-O | DI37: V-O
A38: REQ-033 | B38: View | C38: View | D38: View | E38: Manage | F38: Manage | G38: View | H38: View | I38: View | J38: View | K38: View | L38: View | M38: Control | N38: View | O38: Not applicable | Q38: V | R38: V | S38: V | T38: V | U38: V | V38: V | W38: V | X38: V | Y38: V-O | Z38: V-O | AA38: V-O | AB38: V-O | AC38: V-O | AD38: V-O | AE38: V-O | AG38: V-O | AH38: V-O | AI38: M | AJ38: M | AK38: V-O | AL38: M-O | AM38: M | AN38: M | AO38: M | AQ38: M | AR38: V | AS38: V | AV38: M | AX38: M | AY38: n/a | AZ38: M | BB38: V | BC38: M-O | BD38: M-O | BE38: V | BF38: V | BH38: V | BP38: V | BQ38: V | BT38: C | BU38: C | BW38: V | BZ38: V | CA38: V | CC38: V | CE38: V | CH38: V-O | CJ38: V-O | CK38: V-O | CL38: V-O | CM38: V-O | CN38: V-O | CO38: V-O | CP38: V-O | CQ38: V-O | CS38: V | CT38: V | CU38: V | DD38: V-O | DE38: V-O | DF38: V-O | DG38: V-O | DH38: V-O | DI38: V-O
A39: REQ-034 | B39: View | C39: View | D39: View | E39: Manage | F39: Manage | G39: View | H39: View | I39: View | J39: View | K39: Manage | L39: View | M39: View | N39: View | O39: Not applicable | Q39: V | R39: V | S39: V | T39: V | U39: V | V39: V | W39: V | X39: V | Y39: V-O | Z39: V-O | AA39: V-O | AB39: V-O | AC39: V-O | AD39: V-O | AE39: V-O | AG39: V-O | AH39: V-O | AI39: M | AJ39: M | AK39: V-O | AL39: M-O | AM39: M | AN39: M | AO39: M | AQ39: M | AR39: V | AS39: V | AV39: M | AX39: M | AY39: n/a | AZ39: M | BB39: V | BC39: M-O | BD39: M-O | BE39: V | BF39: V | BH39: V | BI39: M-O | BJ39: M-O | BK39: M-O | BL39: M-O | BM39: M-O | BN39: M-O | BO39: M-O | BP39: V | BQ39: V | BW39: V | BZ39: V | CA39: V | CB39: V | CC39: V | CE39: V | CH39: V-O | CJ39: V-O | CK39: V-O | CL39: V-O | CM39: V-O | CN39: V-O | CO39: V-O | CP39: V-O | CQ39: V-O | CS39: V | CT39: V | CU39: V | DD39: V-O | DE39: V-O | DF39: V-O | DG39: V-O | DH39: V-O | DI39: V-O
A40: REQ-035 | B40: View | C40: View | D40: View | E40: Manage | F40: Manage | G40: View | H40: View | I40: View | J40: View | K40: Manage | L40: View | M40: Manage | N40: View | O40: Not applicable | Q40: V | R40: V | S40: V | T40: V | U40: V | V40: V | W40: V | X40: V | Y40: V-O | Z40: V-O | AA40: V-O | AB40: V-O | AC40: V-O | AD40: V-O | AE40: V-O | AG40: V-O | AH40: V-O | AI40: M | AJ40: M | AK40: V-O | AL40: M-O | AM40: M | AN40: M | AO40: M | AQ40: M | AR40: V | AS40: V | AV40: M | AX40: M | AY40: n/a | AZ40: M | BB40: V | BC40: M-O | BD40: M-O | BE40: V | BF40: V | BH40: V | BI40: M-O | BJ40: M-O | BK40: M-O | BL40: M-O | BM40: M-O | BN40: M-O | BO40: M-O | BP40: V | BQ40: V | BR40: M | BS40: M | BW40: V | BX40: M | BY40: M | BZ40: V | CA40: V | CB40: M | CC40: V | CD40: M | CE40: V | CF40: M-O | CH40: V-O | CJ40: V-O | CK40: V-O | CL40: V-O | CM40: V-O | CN40: V-O | CO40: V-O | CP40: V-O | CQ40: V-O | CS40: V | CT40: V | CU40: V | DD40: V-O | DE40: V-O | DF40: V-O | DG40: V-O | DH40: V-O | DI40: V-O
...

Sheet 20260807 SZ App Integration
A1: Production User Packages
A2: Display Name | D2: Admin Accounts And Profiles | E2: Admin Accounts, Profiles And Servicing | F2: Admin All | G2: Admin Orders | H2: Admin Servicing Requests | I2: Config Platform | J2: Manage Accounts And Profiles | K2: Manage All | L2: Manage Accounts, Profiles, Servicing and Trades Manage All But Not Orders | M2: Manage Firms And Users | N2: Manage Orders | O2: Manage Servicing and Trades | P2: Manage Servicing Requests | Q2: Process Accounts And Profiles | R2: Process Trades | S2: View Only Confidential Profile | T2: Manage Servicing and Orders | U2: Manage Transactions | V2: Manage Orders and Trades | W2: Global Admin | X2: Manage Users | Y2: Manage Users Passwords | Z2: Manage All but not Trades | AA2: Admin All but not Trades | AB2: Admin Orders and Trades | AC2: Full Admin Trades | AD2: Client User Management (new Package; name TBD)
A3: Package Name (current) | D3: AdminAccountsAndProfiles_V1.17 | E3: AdminAllButNotTrade_V1.17 | F3: AdminAll_V1.17 | G3: AdminOrders_V1.17 | H3: AdminServiceRequests_V1.17 | I3: ConfigurePlatformV1.17 | J3: ManageAccountsAndProfiles_V1.17 | K3: ManageAll_V1.17 | L3: ManageAllButNotTrade_v1.16 | M3: ManageFirmAndUser_V1.17 | N3: ManageOrders_V1.17 | O3: ManageServicingandTrades | P3: ManageServiceRequests_V1.17 | Q3: ProcessAccounts_V1.17 | R3: ManagePostTrade_V1.17 | S3: ViewOnlyConfidentialProfile_V1.17 | T3: ManageServicingAndOrders | U3: ManageTransactions_V1.17 | V3: ManageOrdersAndTrades | W3: GlobalAdmin | X3: TBD | Y3: TBD | Z3: TBD | AA3: TBD | AB3: TBD | AC3: TBD | AD3: TBD
A5: Capability Mapping | C5: ACCOUNTS | D5: Open & Modify Accounts | E5: Open & Modify Accounts | F5: Open & Modify Accounts | G5: Open & Modify Accounts | H5: Open & Modify Accounts | I5: Open & Modify Accounts | J5: Open & Modify Accounts | K5: Open & Modify Accounts | L5: Open & Modify Accounts | M5: Open & Modify Accounts | N5: Open & Modify Accounts | O5: Open & Modify Accounts | P5: Open & Modify Accounts | Q5: Open & Modify Accounts | R5: Open & Modify Accounts | S5: Open & Modify Accounts | T5: Open & Modify Accounts | U5: Open & Modify Accounts | V5: Open & Modify Accounts | W5: Open & Modify Accounts | X5: Open & Modify Accounts | Y5: Open & Modify Accounts | Z5: Open & Modify Accounts | AA5: Open & Modify Accounts | AB5: Open & Modify Accounts | AC5: Open & Modify Accounts | AD5: Open & Modify Accounts
C6: SERVICING | D6: Asset Servicing | E6: Asset Servicing | F6: Asset Servicing | G6: Asset Servicing | H6: Asset Servicing | I6: Asset Servicing | J6: Asset Servicing | K6: Asset Servicing | L6: Asset Servicing | M6: Asset Servicing | N6: Asset Servicing | O6: Asset Servicing | P6: Asset Servicing | Q6: Asset Servicing | R6: Asset Servicing | S6: Asset Servicing | T6: Asset Servicing | U6: Asset Servicing | V6: Asset Servicing | W6: Asset Servicing | X6: Asset Servicing | Y6: Asset Servicing | Z6: Asset Servicing | AA6: Asset Servicing | AB6: Asset Servicing | AC6: Asset Servicing | AD6: Asset Servicing
C8: ORDERS | D8: Orders | E8: Orders | F8: Orders | G8: Orders | H8: Orders | I8: Orders | J8: Orders | K8: Orders | L8: Orders | M8: Orders | N8: Orders | O8: Orders | P8: Orders | Q8: Orders | R8: Orders | S8: Orders | T8: Orders | U8: Orders | V8: Orders | W8: Orders | X8: Orders | Y8: Orders | Z8: Orders | AA8: Orders | AB8: Orders | AC8: Orders | AD8: Orders
C9: TRADES | D9: Trades | E9: Trades | F9: Trades | G9: Trades | H9: Trades | I9: Trades | J9: Trades | K9: Trades | L9: Trades | M9: Trades | N9: Trades | O9: Trades | P9: Trades | Q9: Trades | R9: Trades | S9: Trades | T9: Trades | U9: Trades | V9: Trades | W9: Trades | X9: Trades | Y9: Trades | Z9: Trades | AA9: Trades | AB9: Trades | AC9: Trades | AD9: Trades
C11: PLATFORM | D11: Firm Management | E11: Firm Management | F11: Firm Management | G11: Firm Management | H11: Firm Management | I11: Firm Management | J11: Firm Management | K11: Firm Management | L11: Firm Management | M11: Firm Management | N11: Firm Management | O11: Firm Management | P11: Firm Management | Q11: Firm Management | R11: Firm Management | S11: Firm Management | T11: Firm Management | U11: Firm Management | V11: Firm Management | W11: Firm Management | X11: Firm Management | Y11: Firm Management | Z11: Firm Management | AA11: Firm Management | AB11: Firm Management | AC11: Firm Management | AD11: Firm Management
D12: User Management | E12: User Management | F12: User Management | G12: User Management | H12: User Management | I12: User Management | J12: User Management | K12: User Management | L12: User Management | M12: User Management | N12: User Management | O12: User Management | P12: User Management | Q12: User Management | R12: User Management | S12: User Management | T12: User Management | U12: User Management | V12: User Management | W12: User Management | X12: User Management | Y12: User Management | Z12: User Management | AA12: User Management | AB12: User Management | AC12: User Management | AD12: User Management
D13: Configuration | E13: Configuration | F13: Configuration | G13: Configuration | H13: Configuration | I13: Configuration | J13: Configuration | K13: Configuration | L13: Configuration | M13: Configuration | N13: Configuration | O13: Configuration | P13: Configuration | Q13: Configuration | R13: Configuration | S13: Configuration | T13: Configuration | U13: Configuration | V13: Configuration | W13: Configuration | X13: Configuration | Y13: Configuration | Z13: Configuration | AA13: Configuration | AB13: Configuration | AC13: Configuration | AD13: Configuration
A15: Capability Controls | C15: View | D15: 1 | E15: 1 | F15: 1 | G15: 1 | H15: 1 | I15: 1 | J15: 1 | K15: 1 | L15: 1 | M15: 1 | N15: 1 | O15: 1 | P15: 1 | Q15: 1 | R15: 1 | S15: 1 | T15: 1 | U15: 1 | V15: 1 | W15: 1 | X15: 1 | Y15: 1 | Z15: 1 | AA15: 1 | AB15: 1 | AC15: 1
C16: Manage | D16: 1 | E16: 1 | F16: 1 | G16: 1 | H16: 1 | I16: 1 | J16: 1 | K16: 1 | L16: 1 | M16: 1 | N16: 1 | O16: 1 | P16: 1 | Q16: 1 | R16: 1 | S16: 0 | T16: 1 | U16: 1 | V16: 1 | W16: 1 | X16: 1 | Y16: 1 | Z16: 1 | AA16: 1 | AB16: 1 | AC16: 1
C17: Control | D17: 1 | E17: 1 | F17: 1 | G17: 0 | H17: 1 | I17: 0 | J17: 0 | K17: 0 | L17: 0 | M17: 0 | N17: 0 | O17: 0 | P17: 0 | Q17: 0 | R17: 0 | S17: 0 | T17: 0 | U17: 0 | V17: 0 | W17: 1 | X17: 0 | Y17: 0 | Z17: 0 | AA17: 1 | AB17: 1 | AC17: 1
C18: Process | D18: 0 | E18: 0 | F18: 0 | G18: 0 | H18: 0 | I18: 0 | J18: 0 | K18: 0 | L18: 0 | M18: 0 | N18: 0 | O18: 0 | P18: 0 | Q18: 1 | R18: 1 | S18: 0 | T18: 0 | U18: 0 | V18: 0 | W18: 1 | X18: 0 | Y18: 0 | Z18: 0 | AA18: 0 | AB18: 1 | AC18: 1
